2025-07-13 07:46:58,113 -  nornir.core -     INFO -        run() - Running task 'another_show_command_test' with args {} on 4 hosts
2025-07-13 07:46:58,127 - nornir.core.task -    ERROR -      start() - Host 'R1': task 'netmiko_send_command' failed with traceback:
Traceback (most recent call last):
  File "/home/autoomation-vm/Automation/Nornir-Automation/Scrapli/.venv/lib/python3.11/site-packages/netmiko/base_connection.py", line 1146, in establish_connection
    self.remote_conn_pre.connect(**ssh_connect_params)
  File "/home/autoomation-vm/Automation/Nornir-Automation/Scrapli/.venv/lib/python3.11/site-packages/paramiko/client.py", line 409, in connect
    raise NoValidConnectionsError(errors)
paramiko.ssh_exception.NoValidConnectionsError: [Errno None] Unable to connect to port 22 on 192.168.0.11

During handling of the above exception, another exception occurred:

Traceback (most recent call last):
  File "/home/autoomation-vm/Automation/Nornir-Automation/Scrapli/.venv/lib/python3.11/site-packages/nornir/core/task.py", line 98, in start
    r = self.task(self, **self.params)
        ^^^^^^^^^^^^^^^^^^^^^^^^^^^^^^
  File "/home/autoomation-vm/Automation/Nornir-Automation/Scrapli/.venv/lib/python3.11/site-packages/nornir_netmiko/tasks/netmiko_send_command.py", line 26, in netmiko_send_command
    net_connect = task.host.get_connection(CONNECTION_NAME, task.nornir.config)
                  ^^^^^^^^^^^^^^^^^^^^^^^^^^^^^^^^^^^^^^^^^^^^^^^^^^^^^^^^^^^^^
  File "/home/autoomation-vm/Automation/Nornir-Automation/Scrapli/.venv/lib/python3.11/site-packages/nornir/core/inventory.py", line 476, in get_connection
    self.open_connection(
  File "/home/autoomation-vm/Automation/Nornir-Automation/Scrapli/.venv/lib/python3.11/site-packages/nornir/core/inventory.py", line 528, in open_connection
    conn_obj.open(
  File "/home/autoomation-vm/Automation/Nornir-Automation/Scrapli/.venv/lib/python3.11/site-packages/nornir_netmiko/connections/netmiko.py", line 59, in open
    connection = ConnectHandler(**parameters)
                 ^^^^^^^^^^^^^^^^^^^^^^^^^^^^
  File "/home/autoomation-vm/Automation/Nornir-Automation/Scrapli/.venv/lib/python3.11/site-packages/netmiko/ssh_dispatcher.py", line 460, in ConnectHandler
    return ConnectionClass(*args, **kwargs)
           ^^^^^^^^^^^^^^^^^^^^^^^^^^^^^^^^
  File "/home/autoomation-vm/Automation/Nornir-Automation/Scrapli/.venv/lib/python3.11/site-packages/netmiko/base_connection.py", line 495, in __init__
    self._open()
  File "/home/autoomation-vm/Automation/Nornir-Automation/Scrapli/.venv/lib/python3.11/site-packages/netmiko/base_connection.py", line 500, in _open
    self.establish_connection()
  File "/home/autoomation-vm/Automation/Nornir-Automation/Scrapli/.venv/lib/python3.11/site-packages/netmiko/base_connection.py", line 1168, in establish_connection
    raise NetmikoTimeoutException(msg)
netmiko.exceptions.NetmikoTimeoutException: TCP connection to device failed.

Common causes of this problem are:
1. Incorrect hostname or IP address.
2. Wrong TCP port.
3. Intermediate firewall blocking access.

Device settings: cisco_ios 192.168.0.11:22



2025-07-13 07:46:58,128 - nornir.core.task -    ERROR -      start() - Host 'R1': task 'another_show_command_test' failed with traceback:
Traceback (most recent call last):
  File "/home/autoomation-vm/Automation/Nornir-Automation/Scrapli/.venv/lib/python3.11/site-packages/nornir/core/task.py", line 98, in start
    r = self.task(self, **self.params)
        ^^^^^^^^^^^^^^^^^^^^^^^^^^^^^^
  File "/home/autoomation-vm/Automation/Nornir-Automation/Netmiko/show_commands/send_command.py", line 10, in another_show_command_test
    task.run(task=netmiko_send_command , command_string="show interface gi0/0")
  File "/home/autoomation-vm/Automation/Nornir-Automation/Scrapli/.venv/lib/python3.11/site-packages/nornir/core/task.py", line 173, in run
    raise NornirSubTaskError(task=run_task, result=r)
nornir.core.exceptions.NornirSubTaskError: Subtask: netmiko_send_command (failed)


2025-07-13 07:50:03,000 -  nornir.core -     INFO -        run() - Running task 'another_show_commands_test' with args {} on 4 hosts
2025-07-13 07:50:03,005 - nornir.core.task -    ERROR -      start() - Host 'R1': task 'netmiko_send_command' failed with traceback:
Traceback (most recent call last):
  File "/home/autoomation-vm/Automation/Nornir-Automation/Scrapli/.venv/lib/python3.11/site-packages/netmiko/base_connection.py", line 1146, in establish_connection
    self.remote_conn_pre.connect(**ssh_connect_params)
  File "/home/autoomation-vm/Automation/Nornir-Automation/Scrapli/.venv/lib/python3.11/site-packages/paramiko/client.py", line 409, in connect
    raise NoValidConnectionsError(errors)
paramiko.ssh_exception.NoValidConnectionsError: [Errno None] Unable to connect to port 22 on 192.168.0.11

During handling of the above exception, another exception occurred:

Traceback (most recent call last):
  File "/home/autoomation-vm/Automation/Nornir-Automation/Scrapli/.venv/lib/python3.11/site-packages/nornir/core/task.py", line 98, in start
    r = self.task(self, **self.params)
        ^^^^^^^^^^^^^^^^^^^^^^^^^^^^^^
  File "/home/autoomation-vm/Automation/Nornir-Automation/Scrapli/.venv/lib/python3.11/site-packages/nornir_netmiko/tasks/netmiko_send_command.py", line 26, in netmiko_send_command
    net_connect = task.host.get_connection(CONNECTION_NAME, task.nornir.config)
                  ^^^^^^^^^^^^^^^^^^^^^^^^^^^^^^^^^^^^^^^^^^^^^^^^^^^^^^^^^^^^^
  File "/home/autoomation-vm/Automation/Nornir-Automation/Scrapli/.venv/lib/python3.11/site-packages/nornir/core/inventory.py", line 476, in get_connection
    self.open_connection(
  File "/home/autoomation-vm/Automation/Nornir-Automation/Scrapli/.venv/lib/python3.11/site-packages/nornir/core/inventory.py", line 528, in open_connection
    conn_obj.open(
  File "/home/autoomation-vm/Automation/Nornir-Automation/Scrapli/.venv/lib/python3.11/site-packages/nornir_netmiko/connections/netmiko.py", line 59, in open
    connection = ConnectHandler(**parameters)
                 ^^^^^^^^^^^^^^^^^^^^^^^^^^^^
  File "/home/autoomation-vm/Automation/Nornir-Automation/Scrapli/.venv/lib/python3.11/site-packages/netmiko/ssh_dispatcher.py", line 460, in ConnectHandler
    return ConnectionClass(*args, **kwargs)
           ^^^^^^^^^^^^^^^^^^^^^^^^^^^^^^^^
  File "/home/autoomation-vm/Automation/Nornir-Automation/Scrapli/.venv/lib/python3.11/site-packages/netmiko/base_connection.py", line 495, in __init__
    self._open()
  File "/home/autoomation-vm/Automation/Nornir-Automation/Scrapli/.venv/lib/python3.11/site-packages/netmiko/base_connection.py", line 500, in _open
    self.establish_connection()
  File "/home/autoomation-vm/Automation/Nornir-Automation/Scrapli/.venv/lib/python3.11/site-packages/netmiko/base_connection.py", line 1168, in establish_connection
    raise NetmikoTimeoutException(msg)
netmiko.exceptions.NetmikoTimeoutException: TCP connection to device failed.

Common causes of this problem are:
1. Incorrect hostname or IP address.
2. Wrong TCP port.
3. Intermediate firewall blocking access.

Device settings: cisco_ios 192.168.0.11:22



2025-07-13 07:50:03,005 - nornir.core.task -    ERROR -      start() - Host 'R1': task 'another_show_commands_test' failed with traceback:
Traceback (most recent call last):
  File "/home/autoomation-vm/Automation/Nornir-Automation/Scrapli/.venv/lib/python3.11/site-packages/nornir/core/task.py", line 98, in start
    r = self.task(self, **self.params)
        ^^^^^^^^^^^^^^^^^^^^^^^^^^^^^^
  File "/home/autoomation-vm/Automation/Nornir-Automation/Netmiko/show_commands/send_commands.py", line 12, in another_show_commands_test
    task.run(task=netmiko_send_command , command_string=cmd)
  File "/home/autoomation-vm/Automation/Nornir-Automation/Scrapli/.venv/lib/python3.11/site-packages/nornir/core/task.py", line 173, in run
    raise NornirSubTaskError(task=run_task, result=r)
nornir.core.exceptions.NornirSubTaskError: Subtask: netmiko_send_command (failed)


2025-07-13 07:51:30,047 -  nornir.core -     INFO -        run() - Running task 'another_show_commands_test' with args {} on 4 hosts
2025-07-13 07:51:30,052 - nornir.core.task -    ERROR -      start() - Host 'R1': task 'netmiko_send_command' failed with traceback:
Traceback (most recent call last):
  File "/home/autoomation-vm/Automation/Nornir-Automation/Scrapli/.venv/lib/python3.11/site-packages/netmiko/base_connection.py", line 1146, in establish_connection
    self.remote_conn_pre.connect(**ssh_connect_params)
  File "/home/autoomation-vm/Automation/Nornir-Automation/Scrapli/.venv/lib/python3.11/site-packages/paramiko/client.py", line 409, in connect
    raise NoValidConnectionsError(errors)
paramiko.ssh_exception.NoValidConnectionsError: [Errno None] Unable to connect to port 22 on 192.168.0.11

During handling of the above exception, another exception occurred:

Traceback (most recent call last):
  File "/home/autoomation-vm/Automation/Nornir-Automation/Scrapli/.venv/lib/python3.11/site-packages/nornir/core/task.py", line 98, in start
    r = self.task(self, **self.params)
        ^^^^^^^^^^^^^^^^^^^^^^^^^^^^^^
  File "/home/autoomation-vm/Automation/Nornir-Automation/Scrapli/.venv/lib/python3.11/site-packages/nornir_netmiko/tasks/netmiko_send_command.py", line 26, in netmiko_send_command
    net_connect = task.host.get_connection(CONNECTION_NAME, task.nornir.config)
                  ^^^^^^^^^^^^^^^^^^^^^^^^^^^^^^^^^^^^^^^^^^^^^^^^^^^^^^^^^^^^^
  File "/home/autoomation-vm/Automation/Nornir-Automation/Scrapli/.venv/lib/python3.11/site-packages/nornir/core/inventory.py", line 476, in get_connection
    self.open_connection(
  File "/home/autoomation-vm/Automation/Nornir-Automation/Scrapli/.venv/lib/python3.11/site-packages/nornir/core/inventory.py", line 528, in open_connection
    conn_obj.open(
  File "/home/autoomation-vm/Automation/Nornir-Automation/Scrapli/.venv/lib/python3.11/site-packages/nornir_netmiko/connections/netmiko.py", line 59, in open
    connection = ConnectHandler(**parameters)
                 ^^^^^^^^^^^^^^^^^^^^^^^^^^^^
  File "/home/autoomation-vm/Automation/Nornir-Automation/Scrapli/.venv/lib/python3.11/site-packages/netmiko/ssh_dispatcher.py", line 460, in ConnectHandler
    return ConnectionClass(*args, **kwargs)
           ^^^^^^^^^^^^^^^^^^^^^^^^^^^^^^^^
  File "/home/autoomation-vm/Automation/Nornir-Automation/Scrapli/.venv/lib/python3.11/site-packages/netmiko/base_connection.py", line 495, in __init__
    self._open()
  File "/home/autoomation-vm/Automation/Nornir-Automation/Scrapli/.venv/lib/python3.11/site-packages/netmiko/base_connection.py", line 500, in _open
    self.establish_connection()
  File "/home/autoomation-vm/Automation/Nornir-Automation/Scrapli/.venv/lib/python3.11/site-packages/netmiko/base_connection.py", line 1168, in establish_connection
    raise NetmikoTimeoutException(msg)
netmiko.exceptions.NetmikoTimeoutException: TCP connection to device failed.

Common causes of this problem are:
1. Incorrect hostname or IP address.
2. Wrong TCP port.
3. Intermediate firewall blocking access.

Device settings: cisco_ios 192.168.0.11:22



2025-07-13 07:51:30,052 - nornir.core.task -    ERROR -      start() - Host 'R1': task 'another_show_commands_test' failed with traceback:
Traceback (most recent call last):
  File "/home/autoomation-vm/Automation/Nornir-Automation/Scrapli/.venv/lib/python3.11/site-packages/nornir/core/task.py", line 98, in start
    r = self.task(self, **self.params)
        ^^^^^^^^^^^^^^^^^^^^^^^^^^^^^^
  File "/home/autoomation-vm/Automation/Nornir-Automation/Netmiko/show_commands/send_commands.py", line 12, in another_show_commands_test
    task.run(task=netmiko_send_command , command_string=cmd)
  File "/home/autoomation-vm/Automation/Nornir-Automation/Scrapli/.venv/lib/python3.11/site-packages/nornir/core/task.py", line 173, in run
    raise NornirSubTaskError(task=run_task, result=r)
nornir.core.exceptions.NornirSubTaskError: Subtask: netmiko_send_command (failed)


2025-07-13 07:53:18,089 -  nornir.core -     INFO -        run() - Running task 'another_show_commands_test' with args {} on 4 hosts
